Workbook

Sheet Model_Ready_Startups
A1: startup_id | B1: startup_name | C1: hq_country | D1: hq_city | E1: foreign_hq_flag | F1: entity_type | G1: related_startup_id | H1: possible_duplicate_of | I1: founding_year | J1: founding_month | K1: founding_date_precision | L1: baseline_date | M1: months_since_inception | N1: age_years | O1: industry_raw | P1: sector_group | Q1: business_model_raw | R1: is_b2b | S1: is_b2c | T1: is_marketplace | U1: is_subscription_saas | V1: is_hardware_iot | W1: is_transaction_commission | X1: mvp_status_raw | Y1: product_stage | Z1: mvp_built | AA1: accelerator_participated | AB1: accelerator_programs_raw | AC1: prior_grant_flag | AD1: prior_grants_usd | AE1: grant_info_source | AF1: n_founders | AG1: n_male_founders | AH1: n_female_founders | AI1: female_founder_share | AJ1: has_female_founder | AK1: gender_diversity_blau | AL1: team_female_pct_est | AM1: edu_max_level | AN1: edu_max_label | AO1: any_stem_founder | AP1: stem_share | AQ1: serial_entrepreneur | AR1: industry_exp_max_years | AS1: industry_exp_mean_years | AT1: team_size_mid | AU1: team_size_band | AV1: team_size_source | AW1: team_size_note | AX1: survival_status | AY1: status_confidence | AZ1: status_note | BA1: acquired_flag | BB1: is_acquirer | BC1: event_closed | BD1: closure_year | BE1: closure_month | BF1: duration_months | BG1: follow_on_funding_received | BH1: follow_on_funding_usd | BI1: funding_amount_basis | BJ1: follow_on_year | BK1: any_external_funding | BL1: n_accepted_investment_rows | BM1: has_vc_pe | BN1: has_angel | BO1: has_accelerator_investor | BP1: has_corporate | BQ1: has_government | BR1: has_grant_dfi | BS1: evaluation_score_1to5 | BT1: revenue_growth_pct_mid | BU1: employee_growth_pct_mid | BV1: web_visits_mid | BW1: news_mentions_mid | BX1: social_growth_pct_mid | BY1: app_downloads_lb | BZ1: app_rating | CA1: traction_n_components | CB1: traction_composite | CC1: gdp_growth_at_founding | CD1: inflation_at_founding | CE1: gdp_growth_at_funding | CF1: inflation_at_funding | CG1: n_key_fields_missing
A2: BD-ST-001 | B2: bKash | C2: Bangladesh | D2: Dhaka | E2: 0 | F2: Independent startup | I2: 2010 | K2: year | L2: 46295 | M2: =IF(I2="","",(YEAR(L2)-I2)*12+MONTH(L2)-IF(J2="",1,J2)) -> 200 | N2: =IF(M2="","",ROUND(M2/12,2)) -> 16.67 | O2: Fintech / Payments | P2: Fintech | Q2: Mobile Financial Services (MFS) - B2C/B2B agent network | R2: 1 | S2: 1 | T2: 0 | U2: 0 | V2: 0 | W2: 0 | X2: Active (market-mature; unicorn) | Y2: 3 | Z2: 1 | AA2: 0 | AC2: 1 | AD2: 10000000 | AE2: master | AF2: =IF(SUMIF(Founders_Clean!$A$2:$A$159,A2,Founders_Clean!$C$2:$C$159)=0,"",SUMIF(Founders_Clean!$A$2:$A$159,A2,Founders_Clean!$C$2:$C$159)) -> 2 | AG2: =IF(AF2="","",SUMIF(Founders_Clean!$A$2:$A$159,A2,Founders_Clean!$D$2:$D$159)) -> 2 | AH2: =IF(AF2="","",SUMIF(Founders_Clean!$A$2:$A$159,A2,Founders_Clean!$E$2:$E$159)) -> 0 | AI2: =IF(AF2="","",IF((AG2+AH2)=0,"",AH2/(AG2+AH2))) -> 0 | AJ2: =IF(AI2="","",IF(AH2>0,1,0)) -> 0 | AK2: =IF(AI2="","",ROUND(1-(AI2^2+(1-AI2)^2),3)) -> 0 | AM2: 2 | AN2: Master's/MBA/professional | AO2: 1 | AP2: 0.5 | AQ2: 1 | AR2: 25 | AS2: 20 | AT2: 1750 | AU2: 501+ | AV2: LinkedIn (Public_Macro_Data) | AX2: Active | AY2: High | BA2: 0 | BB2: 0 | BC2: 0 | BF2: =IF(OR(I2="",BC2=""),"",IF(BC2=1,(BD2-I2)*12+IF(BE2="",7,BE2)-IF(J2="",1,J2),M2)) -> 200 | BG2: 1 | BH2: 250000000 | BI2: round | BJ2: 2021 | BK2: 1 | BL2: =COUNTIFS(Investments_Clean!$A$2:$A$150,A2,Investments_Clean!$F$2:$F$150,"Accepted") -> 2 | BM2: =IF(BL2=0,"",IF((COUNTIFS(Investments_Clean!$A$2:$A$150,A2,Investments_Clean!$D$2:$D$150,"VC/PE",Investments_Clean!$F$2:$F$150,"Accepted"))>0,1,0)) -> 1 | BN2: =IF(BL2=0,"",IF((COUNTIFS(Investments_Clean!$A$2:$A$150,A2,Investments_Clean!$D$2:$D$150,"Angel",Investments_Clean!$F$2:$F$150,"Accepted"))>0,1,0)) -> 0 | BO2: =IF(BL2=0,"",IF((COUNTIFS(Investments_Clean!$A$2:$A$150,A2,Investments_Clean!$D$2:$D$150,"Accelerator",Investments_Clean!$F$2:$F$150,"Accepted"))>0,1,0)) -> 0 | BP2: =IF(BL2=0,"",IF((COUNTIFS(Investments_Clean!$A$2:$A$150,A2,Investments_Clean!$D$2:$D$150,"Corporate",Investments_Clean!$F$2:$F$150,"Accepted"))>0,1,0)) -> 0 | BQ2: =IF(BL2=0,"",IF((COUNTIFS(Investments_Clean!$A$2:$A$150,A2,Investments_Clean!$D$2:$D$150,"Government",Investments_Clean!$F$2:$F$150,"Accepted"))>0,1,0)) -> 0 | BR2: =IF(BL2=0,"",IF((COUNTIFS(Investments_Clean!$A$2:$A$150,A2,Investments_Clean!$D$2:$D$150,"Grant/Philanthropic",Investments_Clean!$F$2:$F$150,"Accepted")+COUNTIFS(Investments_Clean!$A$2:$A$150,A2,Investments_Clean!$D$2:$D$150,"DFI/Impact",Investments_Clean!$F$2:$F$150,"Accepted"))>0,1,0)) -> 1 | CA2: 0 | CC2: =IF(I2="","",IFERROR(IF(INDEX(Macro_Lookup!$B$2:$B$31,MATCH(I2,Macro_Lookup!$A$2:$A$31,0))="","",INDEX(Macro_Lookup!$B$2:$B$31,MATCH(I2,Macro_Lookup!$A$2:$A$31,0))),"")) -> 5.57 | CD2: =IF(I2="","",IFERROR(IF(INDEX(Macro_Lookup!$C$2:$C$31,MATCH(I2,Macro_Lookup!$A$2:$A$31,0))="","",INDEX(Macro_Lookup!$C$2:$C$31,MATCH(I2,Macro_Lookup!$A$2:$A$31,0))),"")) -> 7.3 | CE2: =IF(BJ2="","",IFERROR(IF(INDEX(Macro_Lookup!$B$2:$B$31,MATCH(BJ2,Macro_Lookup!$A$2:$A$31,0))="","",INDEX(Macro_Lookup!$B$2:$B$31,MATCH(BJ2,Macro_Lookup!$A$2:$A$31,0))),"")) -> 6.94 | CF2: =IF(BJ2="","",IFERROR(IF(INDEX(Macro_Lookup!$C$2:$C$31,MATCH(BJ2,Macro_Lookup!$A$2:$A$31,0))="","",INDEX(Macro_Lookup!$C$2:$C$31,MATCH(BJ2,Macro_Lookup!$A$2:$A$31,0))),"")) -> 5.55 | CG2: 1
A3: BD-ST-002 | B3: Nagad | C3: Bangladesh | D3: Dhaka | E3: 0 | F3: Independent startup | I3: 2019 | K3: year | L3: 46295 | M3: =IF(I3="","",(YEAR(L3)-I3)*12+MONTH(L3)-IF(J3="",1,J3)) -> 92 | N3: =IF(M3="","",ROUND(M3/12,2)) -> 7.67 | O3: Fintech / Payments | P3: Fintech | Q3: MFS (Public-Private Partnership w/ Bangladesh Post Office) | R3: 0 | S3: 0 | T3: 0 | U3: 0 | V3: 0 | W3: 0 | X3: Active | Y3: 3 | Z3: 1 | AF3: =IF(SUMIF(Founders_Clean!$A$2:$A$159,A3,Founders_Clean!$C$2:$C$159)=0,"",SUMIF(Founders_Clean!$A$2:$A$159,A3,Founders_Clean!$C$2:$C$159)) -> 1 | AG3: =IF(AF3="","",SUMIF(Founders_Clean!$A$2:$A$159,A3,Founders_Clean!$D$2:$D$159)) -> 1 | AH3: =IF(AF3="","",SUMIF(Founders_Clean!$A$2:$A$159,A3,Founders_Clean!$E$2:$E$159)) -> 0 | AI3: =IF(AF3="","",IF((AG3+AH3)=0,"",AH3/(AG3+AH3))) -> 0 | AJ3: =IF(AI3="","",IF(AH3>0,1,0)) -> 0 | AK3: =IF(AI3="","",ROUND(1-(AI3^2+(1-AI3)^2),3)) -> 0 | AM3: 2 | AN3: Master's/MBA/professional | AO3: 0 | AP3: 0 | AQ3: 1 | AR3: 11 | AS3: 11 | AT3: 1000 | AU3: 501+ | AV3: LinkedIn (Public_Macro_Data) | AX3: Active | AY3: High | BA3: 0 | BB3: 0 | BC3: 0 | BF3: =IF(OR(I3="",BC3=""),"",IF(BC3=1,(BD3-I3)*12+IF(BE3="",7,BE3)-IF(J3="",1,J3),M3)) -> 92 | BG3: 1 | BI3: unknown | BJ3: 2026 | BK3: 1 | BL3: =COUNTIFS(Investments_Clean!$A$2:$A$150,A3,Investments_Clean!$F$2:$F$150,"Accepted") -> 2 | BM3: =IF(BL3=0,"",IF((COUNTIFS(Investments_Clean!$A$2:$A$150,A3,Investments_Clean!$D$2:$D$150,"VC/PE",Investments_Clean!$F$2:$F$150,"Accepted"))>0,1,0)) -> 0 | BN3: =IF(BL3=0,"",IF((COUNTIFS(Investments_Clean!$A$2:$A$150,A3,Investments_Clean!$D$2:$D$150,"Angel",Investments_Clean!$F$2:$F$150,"Accepted"))>0,1,0)) -> 0 | BO3: =IF(BL3=0,"",IF((COUNTIFS(Investments_Clean!$A$2:$A$150,A3,Investments_Clean!$D$2:$D$150,"Accelerator",Investments_Clean!$F$2:$F$150,"Accepted"))>0,1,0)) -> 0 | BP3: =IF(BL3=0,"",IF((COUNTIFS(Investments_Clean!$A$2:$A$150,A3,Investments_Clean!$D$2:$D$150,"Corporate",Investments_Clean!$F$2:$F$150,"Accepted"))>0,1,0)) -> 1 | BQ3: =IF(BL3=0,"",IF((COUNTIFS(Investments_Clean!$A$2:$A$150,A3,Investments_Clean!$D$2:$D$150,"Government",Investments_Clean!$F$2:$F$150,"Accepted"))>0,1,0)) -> 1 | BR3: =IF(BL3=0,"",IF((COUNTIFS(Investments_Clean!$A$2:$A$150,A3,Investments_Clean!$D$2:$D$150,"Grant/Philanthropic",Investments_Clean!$F$2:$F$150,"Accepted")+COUNTIFS(Investments_Clean!$A$2:$A$150,A3,Investments_Clean!$D$2:$D$150,"DFI/Impact",Investments_Clean!$F$2:$F$150,"Accepted"))>0,1,0)) -> 0 | CA3: 0 | CC3: =IF(I3="","",IFERROR(IF(INDEX(Macro_Lookup!$B$2:$B$31,MATCH(I3,Macro_Lookup!$A$2:$A$31,0))="","",INDEX(Macro_Lookup!$B$2:$B$31,MATCH(I3,Macro_Lookup!$A$2:$A$31,0))),"")) -> 7.88 | CD3: =IF(I3="","",IFERROR(IF(INDEX(Macro_Lookup!$C$2:$C$31,MATCH(I3,Macro_Lookup!$A$2:$A$31,0))="","",INDEX(Macro_Lookup!$C$2:$C$31,MATCH(I3,Macro_Lookup!$A$2:$A$31,0))),"")) -> 5.5 | CE3: =IF(BJ3="","",IFERROR(IF(INDEX(Macro_Lookup!$B$2:$B$31,MATCH(BJ3,Macro_Lookup!$A$2:$A$31,0))="","",INDEX(Macro_Lookup!$B$2:$B$31,MATCH(BJ3,Macro_Lookup!$A$2:$A$31,0))),"")) | CF3: =IF(BJ3="","",IFERROR(IF(INDEX(Macro_Lookup!$C$2:$C$31,MATCH(BJ3,Macro_Lookup!$A$2:$A$31,0))="","",INDEX(Macro_Lookup!$C$2:$C$31,MATCH(BJ3,Macro_Lookup!$A$2:$A$31,0))),"")) -> 9.16 | CG3: 3
A4: BD-ST-003 | B4: Rocket (DBBL Mobile Banking) | C4: Bangladesh | D4: Dhaka | E4: 0 | F4: Corporate division/subsidiary | I4: 2011 | K4: year | L4: 46295 | M4: =IF(I4="","",(YEAR(L4)-I4)*12+MONTH(L4)-IF(J4="",1,J4)) -> 188 | N4: =IF(M4="","",ROUND(M4/12,2)) -> 15.67 | O4: Fintech / Payments | P4: Fintech | Q4: Bank-led MFS Payments (DBBL subsidiary) | R4: 0 | S4: 0 | T4: 0 | U4: 0 | V4: 0 | W4: 0 | X4: Active | Y4: 3 | Z4: 1 | AF4: =IF(SUMIF(Founders_Clean!$A$2:$A$159,A4,Founders_Clean!$C$2:$C$159)=0,"",SUMIF(Founders_Clean!$A$2:$A$159,A4,Founders_Clean!$C$2:$C$159)) -> 1 | AG4: =IF(AF4="","",SUMIF(Founders_Clean!$A$2:$A$159,A4,Founders_Clean!$D$2:$D$159)) -> 1 | AH4: =IF(AF4="","",SUMIF(Founders_Clean!$A$2:$A$159,A4,Founders_Clean!$E$2:$E$159)) -> 0 | AI4: =IF(AF4="","",IF((AG4+AH4)=0,"",AH4/(AG4+AH4))) -> 0 | AJ4: =IF(AI4="","",IF(AH4>0,1,0)) -> 0 | AK4: =IF(AI4="","",ROUND(1-(AI4^2+(1-AI4)^2),3)) -> 0 | AR4: 30 | AS4: 30 | AV4: excluded | AW4: Value is Dutch-Bangla Bank group headcount (projected), not Rocket team size | AX4: Active | AY4: High | BA4: 0 | BB4: 0 | BC4: 0 | BF4: =IF(OR(I4="",BC4=""),"",IF(BC4=1,(BD4-I4)*12+IF(BE4="",7,BE4)-IF(J4="",1,J4),M4)) -> 188 | BG4: 0 | BH4: 0 | BI4: none | BK4: 0 | BL4: =COUNTIFS(Investments_Clean!$A$2:$A$150,A4,Investments_Clean!$F$2:$F$150,"Accepted") -> 1 | BM4: =IF(BL4=0,"",IF((COUNTIFS(Investments_Clean!$A$2:$A$150,A4,Investments_Clean!$D$2:$D$150,"VC/PE",Investments_Clean!$F$2:$F$150,"Accepted"))>0,1,0)) -> 0 | BN4: =IF(BL4=0,"",IF((COUNTIFS(Investments_Clean!$A$2:$A$150,A4,Investments_Clean!$D$2:$D$150,"Angel",Investments_Clean!$F$2:$F$150,"Accepted"))>0,1,0)) -> 0 | BO4: =IF(BL4=0,"",IF((COUNTIFS(Investments_Clean!$A$2:$A$150,A4,Investments_Clean!$D$2:$D$150,"Accelerator",Investments_Clean!$F$2:$F$150,"Accepted"))>0,1,0)) -> 0 | BP4: =IF(BL4=0,"",IF((COUNTIFS(Investments_Clean!$A$2:$A$150,A4,Investments_Clean!$D$2:$D$150,"Corporate",Investments_Clean!$F$2:$F$150,"Accepted"))>0,1,0)) -> 0 | BQ4: =IF(BL4=0,"",IF((COUNTIFS(Investments_Clean!$A$2:$A$150,A4,Investments_Clean!$D$2:$D$150,"Government",Investments_Clean!$F$2:$F$150,"Accepted"))>0,1,0)) -> 0 | BR4: =IF(BL4=0,"",IF((COUNTIFS(Investments_Clean!$A$2:$A$150,A4,Investments_Clean!$D$2:$D$150,"Grant/Philanthropic",Investments_Clean!$F$2:$F$150,"Accepted")+COUNTIFS(Investments_Clean!$A$2:$A$150,A4,Investments_Clean!$D$2:$D$150,"DFI/Impact",Investments_Clean!$F$2:$F$150,"Accepted"))>0,1,0)) -> 0 | CA4: 0 | CC4: =IF(I4="","",IFERROR(IF(INDEX(Macro_Lookup!$B$2:$B$31,MATCH(I4,Macro_Lookup!$A$2:$A$31,0))="","",INDEX(Macro_Lookup!$B$2:$B$31,MATCH(I4,Macro_Lookup!$A$2:$A$31,0))),"")) -> 6.46 | CD4: =IF(I4="","",IFERROR(IF(INDEX(Macro_Lookup!$C$2:$C$31,MATCH(I4,Macro_Lookup!$A$2:$A$31,0))="","",INDEX(Macro_Lookup!$C$2:$C$31,MATCH(I4,Macro_Lookup!$A$2:$A$31,0))),"")) -> 11.4 | CE4: =IF(BJ4="","",IFERROR(IF(INDEX(Macro_Lookup!$B$2:$B$31,MATCH(BJ4,Macro_Lookup!$A$2:$A$31,0))="","",INDEX(Macro_Lookup!$B$2:$B$31,MATCH(BJ4,Macro_Lookup!$A$2:$A$31,0))),"")) | CF4: =IF(BJ4="","",IFERROR(IF(INDEX(Macro_Lookup!$C$2:$C$31,MATCH(BJ4,Macro_Lookup!$A$2:$A$31,0))="","",INDEX(Macro_Lookup!$C$2:$C$31,MATCH(BJ4,Macro_Lookup!$A$2:$A$31,0))),"")) | CG4: 5
A5: BD-ST-004 | B5: SureCash | C5: Bangladesh | D5: Dhaka | E5: 0 | F5: Independent startup | I5: 2010 | K5: year | L5: 46295 | M5: =IF(I5="","",(YEAR(L5)-I5)*12+MONTH(L5)-IF(J5="",1,J5)) -> 200 | N5: =IF(M5="","",ROUND(M5/12,2)) -> 16.67 | O5: Fintech / Payments | P5: Fintech | Q5: Payment Network Rails / Interoperability Infrastructure | R5: 0 | S5: 0 | T5: 0 | U5: 0 | V5: 0 | W5: 0 | X5: Active | Y5: 3 | Z5: 1 | AA5: 0 | AF5: =IF(SUMIF(Founders_Clean!$A$2:$A$159,A5,Founders_Clean!$C$2:$C$159)=0,"",SUMIF(Founders_Clean!$A$2:$A$159,A5,Founders_Clean!$C$2:$C$159)) -> 1 | AG5: =IF(AF5="","",SUMIF(Founders_Clean!$A$2:$A$159,A5,Founders_Clean!$D$2:$D$159)) -> 1 | AH5: =IF(AF5="","",SUMIF(Founders_Clean!$A$2:$A$159,A5,Founders_Clean!$E$2:$E$159)) -> 0 | AI5: =IF(AF5="","",IF((AG5+AH5)=0,"",AH5/(AG5+AH5))) -> 0 | AJ5: =IF(AI5="","",IF(AH5>0,1,0)) -> 0 | AK5: =IF(AI5="","",ROUND(1-(AI5^2+(1-AI5)^2),3)) -> 0 | AM5: 3 | AN5: PhD | AO5: 1 | AP5: 1 | AQ5: 1 | AR5: 23 | AS5: 23 | AT5: 260 | AU5: 201-500 | AV5: Founders_Team | AX5: Active | AY5: High | BA5: 0 | BB5: 0 | BC5: 0 | BF5: =IF(OR(I5="",BC5=""),"",IF(BC5=1,(BD5-I5)*12+IF(BE5="",7,BE5)-IF(J5="",1,J5),M5)) -> 200 | BG5: 1 | BH5: 7000000 | BI5: round | BJ5: 2015 | BK5: 1 | BL5: =COUNTIFS(Investments_Clean!$A$2:$A$150,A5,Investments_Clean!$F$2:$F$150,"Accepted") -> 1 | BM5: =IF(BL5=0,"",IF((COUNTIFS(Investments_Clean!$A$2:$A$150,A5,Investments_Clean!$D$2:$D$150,"VC/PE",Investments_Clean!$F$2:$F$150,"Accepted"))>0,1,0)) -> 1 | BN5: =IF(BL5=0,"",IF((COUNTIFS(Investments_Clean!$A$2:$A$150,A5,Investments_Clean!$D$2:$D$150,"Angel",Investments_Clean!$F$2:$F$150,"Accepted"))>0,1,0)) -> 0 | BO5: =IF(BL5=0,"",IF((COUNTIFS(Investments_Clean!$A$2:$A$150,A5,Investments_Clean!$D$2:$D$150,"Accelerator",Investments_Clean!$F$2:$F$150,"Accepted"))>0,1,0)) -> 0 | BP5: =IF(BL5=0,"",IF((COUNTIFS(Investments_Clean!$A$2:$A$150,A5,Investments_Clean!$D$2:$D$150,"Corporate",Investments_Clean!$F$2:$F$150,"Accepted"))>0,1,0)) -> 0 | BQ5: =IF(BL5=0,"",IF((COUNTIFS(Investments_Clean!$A$2:$A$150,A5,Investments_Clean!$D$2:$D$150,"Government",Investments_Clean!$F$2:$F$150,"Accepted"))>0,1,0)) -> 0 | BR5: =IF(BL5=0,"",IF((COUNTIFS(Investments_Clean!$A$2:$A$150,A5,Investments_Clean!$D$2:$D$150,"Grant/Philanthropic",Investments_Clean!$F$2:$F$150,"Accepted")+COUNTIFS(Investments_Clean!$A$2:$A$150,A5,Investments_Clean!$D$2:$D$150,"DFI/Impact",Investments_Clean!$F$2:$F$150,"Accepted"))>0,1,0)) -> 0 | CA5: 0 | CC5: =IF(I5="","",IFERROR(IF(INDEX(Macro_Lookup!$B$2:$B$31,MATCH(I5,Macro_Lookup!$A$2:$A$31,0))="","",INDEX(Macro_Lookup!$B$2:$B$31,MATCH(I5,Macro_Lookup!$A$2:$A$31,0))),"")) -> 5.57 | CD5: =IF(I5="","",IFERROR(IF(INDEX(Macro_Lookup!$C$2:$C$31,MATCH(I5,Macro_Lookup!$A$2:$A$31,0))="","",INDEX(Macro_Lookup!$C$2:$C$31,MATCH(I5,Macro_Lookup!$A$2:$A$31,0))),"")) -> 7.3 | CE5: =IF(BJ5="","",IFERROR(IF(INDEX(Macro_Lookup!$B$2:$B$31,MATCH(BJ5,Macro_Lookup!$A$2:$A$31,0))="","",INDEX(Macro_Lookup!$B$2:$B$31,MATCH(BJ5,Macro_Lookup!$A$2:$A$31,0))),"")) -> 6.55 | CF5: =IF(BJ5="","",IFERROR(IF(INDEX(Macro_Lookup!$C$2:$C$31,MATCH(BJ5,Macro_Lookup!$A$2:$A$31,0))="","",INDEX(Macro_Lookup!$C$2:$C$31,MATCH(BJ5,Macro_Lookup!$A$2:$A$31,0))),"")) -> 6.4 | CG5: 2
A6: BD-ST-005 | B6: Upay | C6: Bangladesh | D6: Dhaka | E6: 0 | F6: Corporate division/subsidiary | G6: BD-ST-008 | I6: 2021 | K6: year | L6: 46295 | M6: =IF(I6="","",(YEAR(L6)-I6)*12+MONTH(L6)-IF(J6="",1,J6)) -> 68 | N6: =IF(M6="","",ROUND(M6/12,2)) -> 5.67 | O6: Fintech / Payments | P6: Fintech | Q6: MFS (blockchain-based ledger; UCB subsidiary) | R6: 0 | S6: 0 | T6: 0 | U6: 0 | V6: 0 | W6: 0 | X6: Active | Y6: 3 | Z6: 1 | AF6: =IF(SUMIF(Founders_Clean!$A$2:$A$159,A6,Founders_Clean!$C$2:$C$159)=0,"",SUMIF(Founders_Clean!$A$2:$A$159,A6,Founders_Clean!$C$2:$C$159)) -> 1 | AG6: =IF(AF6="","",SUMIF(Founders_Clean!$A$2:$A$159,A6,Founders_Clean!$D$2:$D$159)) -> 1 | AH6: =IF(AF6="","",SUMIF(Founders_Clean!$A$2:$A$159,A6,Founders_Clean!$E$2:$E$159)) -> 0 | AI6: =IF(AF6="","",IF((AG6+AH6)=0,"",AH6/(AG6+AH6))) -> 0 | AJ6: =IF(AI6="","",IF(AH6>0,1,0)) -> 0 | AK6: =IF(AI6="","",ROUND(1-(AI6^2+(1-AI6)^2),3)) -> 0 | AM6: 2 | AN6: Master's/MBA/professional | AO6: 0 | AP6: 0 | AQ6: 0 | AR6: 20 | AS6: 20 | AT6: 350 | AU6: 201-500 | AV6: LinkedIn (Public_Macro_Data) | AX6: Active | AY6: High | BA6: 0 | BB6: 0 | BC6: 0 | BF6: =IF(OR(I6="",BC6=""),"",IF(BC6=1,(BD6-I6)*12+IF(BE6="",7,BE6)-IF(J6="",1,J6),M6)) -> 68 | BG6: 0 | BH6: 0 | BI6: none | BJ6: 2021 | BK6: 0 | BL6: =COUNTIFS(Investments_Clean!$A$2:$A$150,A6,Investments_Clean!$F$2:$F$150,"Accepted") -> 1 | BM6: =IF(BL6=0,"",IF((COUNTIFS(Investments_Clean!$A$2:$A$150,A6,Investments_Clean!$D$2:$D$150,"VC/PE",Investments_Clean!$F$2:$F$150,"Accepted"))>0,1,0)) -> 0 | BN6: =IF(BL6=0,"",IF((COUNTIFS(Investments_Clean!$A$2:$A$150,A6,Investments_Clean!$D$2:$D$150,"Angel",Investments_Clean!$F$2:$F$150,"Accepted"))>0,1,0)) -> 0 | BO6: =IF(BL6=0,"",IF((COUNTIFS(Investments_Clean!$A$2:$A$150,A6,Investments_Clean!$D$2:$D$150,"Accelerator",Investments_Clean!$F$2:$F$150,"Accepted"))>0,1,0)) -> 0 | BP6: =IF(BL6=0,"",IF((COUNTIFS(Investments_Clean!$A$2:$A$150,A6,Investments_Clean!$D$2:$D$150,"Corporate",Investments_Clean!$F$2:$F$150,"Accepted"))>0,1,0)) -> 0 | BQ6: =IF(BL6=0,"",IF((COUNTIFS(Investments_Clean!$A$2:$A$150,A6,Investments_Clean!$D$2:$D$150,"Government",Investments_Clean!$F$2:$F$150,"Accepted"))>0,1,0)) -> 0 | BR6: =IF(BL6=0,"",IF((COUNTIFS(Investments_Clean!$A$2:$A$150,A6,Investments_Clean!$D$2:$D$150,"Grant/Philanthropic",Investments_Clean!$F$2:$F$150,"Accepted")+COUNTIFS(Investments_Clean!$A$2:$A$150,A6,Investments_Clean!$D$2:$D$150,"DFI/Impact",Investments_Clean!$F$2:$F$150,"Accepted"))>0,1,0)) -> 0 | CA6: 0 | CC6: =IF(I6="","",IFERROR(IF(INDEX(Macro_Lookup!$B$2:$B$31,MATCH(I6,Macro_Lookup!$A$2:$A$31,0))="","",INDEX(Macro_Lookup!$B$2:$B$31,MATCH(I6,Macro_Lookup!$A$2:$A$31,0))),"")) -> 6.94 | CD6: =IF(I6="","",IFERROR(IF(INDEX(Macro_Lookup!$C$2:$C$31,MATCH(I6,Macro_Lookup!$A$2:$A$31,0))="","",INDEX(Macro_Lookup!$C$2:$C$31,MATCH(I6,Macro_Lookup!$A$2:$A$31,0))),"")) -> 5.55 | CE6: =IF(BJ6="","",IFERROR(IF(INDEX(Macro_Lookup!$B$2:$B$31,MATCH(BJ6,Macro_Lookup!$A$2:$A$31,0))="","",INDEX(Macro_Lookup!$B$2:$B$31,MATCH(BJ6,Macro_Lookup!$A$2:$A$31,0))),"")) -> 6.94 | CF6: =IF(BJ6="","",IFERROR(IF(INDEX(Macro_Lookup!$C$2:$C$31,MATCH(BJ6,Macro_Lookup!$A$2:$A$31,0))="","",INDEX(Macro_Lookup!$C$2:$C$31,MATCH(BJ6,Macro_Lookup!$A$2:$A$31,0))),"")) -> 5.55 | CG6: 3
A7: BD-ST-006 | B7: Dmoney | C7: Bangladesh | D7: Dhaka | E7: 0 | F7: Independent startup | I7: 2016 | K7: year | L7: 46295 | M7: =IF(I7="","",(YEAR(L7)-I7)*12+MONTH(L7)-IF(J7="",1,J7)) -> 128 | N7: =IF(M7="","",ROUND(M7/12,2)) -> 10.67 | O7: Fintech / Payments | P7: Fintech | Q7: Digital Wallet | R7: 0 | S7: 0 | T7: 0 | U7: 0 | V7: 0 | W7: 0 | X7: Active | Y7: 3 | Z7: 1 | AF7: =IF(SUMIF(Founders_Clean!$A$2:$A$159,A7,Founders_Clean!$C$2:$C$159)=0,"",SUMIF(Founders_Clean!$A$2:$A$159,A7,Founders_Clean!$C$2:$C$159)) -> 2 | AG7: =IF(AF7="","",SUMIF(Founders_Clean!$A$2:$A$159,A7,Founders_Clean!$D$2:$D$159)) -> 1 | AH7: =IF(AF7="","",SUMIF(Founders_Clean!$A$2:$A$159,A7,Founders_Clean!$E$2:$E$159)) -> 1 | AI7: =IF(AF7="","",IF((AG7+AH7)=0,"",AH7/(AG7+AH7))) -> 0.5 | AJ7: =IF(AI7="","",IF(AH7>0,1,0)) -> 1 | AK7: =IF(AI7="","",ROUND(1-(AI7^2+(1-AI7)^2),3)) -> 0.5 | AM7: 2 | AN7: Master's/MBA/professional | AO7: 1 | AP7: 1 | AQ7: 1 | AR7: 25 | AS7: 22.5 | AT7: 150 | AU7: 51-200 | AV7: LinkedIn (Public_Macro_Data) | AX7: Active | AY7: High | BA7: 0 | BB7: 0 | BC7: 0 | BF7: =IF(OR(I7="",BC7=""),"",IF(BC7=1,(BD7-I7)*12+IF(BE7="",7,BE7)-IF(J7="",1,J7),M7)) -> 128 | BG7: 1 | BH7: 5000000 | BI7: round | BJ7: 2019 | BK7: 1 | BL7: =COUNTIFS(Investments_Clean!$A$2:$A$150,A7,Investments_Clean!$F$2:$F$150,"Accepted") -> 1 | BM7: =IF(BL7=0,"",IF((COUNTIFS(Investments_Clean!$A$2:$A$150,A7,Investments_Clean!$D$2:$D$150,"VC/PE",Investments_Clean!$F$2:$F$150,"Accepted"))>0,1,0)) -> 0 | BN7: =IF(BL7=0,"",IF((COUNTIFS(Investments_Clean!$A$2:$A$150,A7,Investments_Clean!$D$2:$D$150,"Angel",Investments_Clean!$F$2:$F$150,"Accepted"))>0,1,0)) -> 0 | BO7: =IF(BL7=0,"",IF((COUNTIFS(Investments_Clean!$A$2:$A$150,A7,Investments_Clean!$D$2:$D$150,"Accelerator",Investments_Clean!$F$2:$F$150,"Accepted"))>0,1,0)) -> 0 | BP7: =IF(BL7=0,"",IF((COUNTIFS(Investments_Clean!$A$2:$A$150,A7,Investments_Clean!$D$2:$D$150,"Corporate",Investments_Clean!$F$2:$F$150,"Accepted"))>0,1,0)) -> 1 | BQ7: =IF(BL7=0,"",IF((COUNTIFS(Investments_Clean!$A$2:$A$150,A7,Investments_Clean!$D$2:$D$150,"Government",Investments_Clean!$F$2:$F$150,"Accepted"))>0,1,0)) -> 0 | BR7: =IF(BL7=0,"",IF((COUNTIFS(Investments_Clean!$A$2:$A$150,A7,Investments_Clean!$D$2:$D$150,"Grant/Philanthropic",Investments_Clean!$F$2:$F$150,"Accepted")+COUNTIFS(Investments_Clean!$A$2:$A$150,A7,Investments_Clean!$D$2:$D$150,"DFI/Impact",Investments_Clean!$F$2:$F$150,"Accepted"))>0,1,0)) -> 0 | CA7: 0 | CC7: =IF(I7="","",IFERROR(IF(INDEX(Macro_Lookup!$B$2:$B$31,MATCH(I7,Macro_Lookup!$A$2:$A$31,0))="","",INDEX(Macro_Lookup!$B$2:$B$31,MATCH(I7,Macro_Lookup!$A$2:$A$31,0))),"")) -> 7.11 | CD7: =IF(I7="","",IFERROR(IF(INDEX(Macro_Lookup!$C$2:$C$31,MATCH(I7,Macro_Lookup!$A$2:$A$31,0))="","",INDEX(Macro_Lookup!$C$2:$C$31,MATCH(I7,Macro_Lookup!$A$2:$A$31,0))),"")) -> 5.51 | CE7: =IF(BJ7="","",IFERROR(IF(INDEX(Macro_Lookup!$B$2:$B$31,MATCH(BJ7,Macro_Lookup!$A$2:$A$31,0))="","",INDEX(Macro_Lookup!$B$2:$B$31,MATCH(BJ7,Macro_Lookup!$A$2:$A$31,0))),"")) -> 7.88 | CF7: =IF(BJ7="","",IFERROR(IF(INDEX(Macro_Lookup!$C$2:$C$31,MATCH(BJ7,Macro_Lookup!$A$2:$A$31,0))="","",INDEX(Macro_Lookup!$C$2:$C$31,MATCH(BJ7,Macro_Lookup!$A$2:$A$31,0))),"")) -> 5.5 | CG7: 3
A8: BD-ST-007 | B8: PayWell | C8: Bangladesh | D8: Dhaka | E8: 0 | F8: Independent startup | I8: 2012 | J8: 11 | K8: month | L8: 46295 | M8: =IF(I8="","",(YEAR(L8)-I8)*12+MONTH(L8)-IF(J8="",1,J8)) -> 166 | N8: =IF(M8="","",ROUND(M8/12,2)) -> 13.83 | O8: Fintech / Payments | P8: Fintech | Q8: B2C/B2B utility, telecom & financial transaction retail aggregator (POS/agent network) | R8: 1 | S8: 1 | T8: 1 | U8: 0 | V8: 0 | W8: 1 | X8: Acquired (by ShopUp, Bangladeshi B2B commerce platform) | Y8: 3 | Z8: 1 | AC8: 0 | AD8: 0 | AE8: master | AF8: =IF(SUMIF(Founders_Clean!$A$2:$A$159,A8,Founders_Clean!$C$2:$C$159)=0,"",SUMIF(Founders_Clean!$A$2:$A$159,A8,Founders_Clean!$C$2:$C$159)) -> 2 | AG8: =IF(AF8="","",SUMIF(Founders_Clean!$A$2:$A$159,A8,Founders_Clean!$D$2:$D$159)) -> 1 | AH8: =IF(AF8="","",SUMIF(Founders_Clean!$A$2:$A$159,A8,Founders_Clean!$E$2:$E$159)) -> 0 | AI8: =IF(AF8="","",IF((AG8+AH8)=0,"",AH8/(AG8+AH8))) -> 0 | AJ8: =IF(AI8="","",IF(AH8>0,1,0)) -> 0 | AK8: =IF(AI8="","",ROUND(1-(AI8^2+(1-AI8)^2),3)) -> 0 | AM8: 0 | AN8: Below bachelor | AO8: 0 | AP8: 0 | AQ8: 1 | AR8: 15 | AS8: 15 | AT8: 200 | AU8: 51-200 | AV8: Founders_Team | AW8: Parent-company scale (CloudWell), not PayWell alone | AX8: Acquired | AY8: High | BA8: 1 | BB8: 0 | BC8: 0 | BF8: =IF(OR(I8="",BC8=""),"",IF(BC8=1,(BD8-I8)*12+IF(BE8="",7,BE8)-IF(J8="",1,J8),M8)) -> 166 | BL8: =COUNTIFS(Investments_Clean!$A$2:$A$150,A8,Investments_Clean!$F$2:$F$150,"Accepted") -> 0 | BM8: =IF(BL8=0,"",IF((COUNTIFS(Investments_Clean!$A$2:$A$150,A8,Investments_Clean!$D$2:$D$150,"VC/PE",Investments_Clean!$F$2:$F$150,"Accepted"))>0,1,0)) | BN8: =IF(BL8=0,"",IF((COUNTIFS(Investments_Clean!$A$2:$A$150,A8,Investments_Clean!$D$2:$D$150,"Angel",Investments_Clean!$F$2:$F$150,"Accepted"))>0,1,0)) | BO8: =IF(BL8=0,"",IF((COUNTIFS(Investments_Clean!$A$2:$A$150,A8,Investments_Clean!$D$2:$D$150,"Accelerator",Investments_Clean!$F$2:$F$150,"Accepted"))>0,1,0)) | BP8: =IF(BL8=0,"",IF((COUNTIFS(Investments_Clean!$A$2:$A$150,A8,Investments_Clean!$D$2:$D$150,"Corporate",Investments_Clean!$F$2:$F$150,"Accepted"))>0,1,0)) | BQ8: =IF(BL8=0,"",IF((COUNTIFS(Investments_Clean!$A$2:$A$150,A8,Investments_Clean!$D$2:$D$150,"Government",Investments_Clean!$F$2:$F$150,"Accepted"))>0,1,0)) | BR8: =IF(BL8=0,"",IF((COUNTIFS(Investments_Clean!$A$2:$A$150,A8,Investments_Clean!$D$2:$D$150,"Grant/Philanthropic",Investments_Clean!$F$2:$F$150,"Accepted")+COUNTIFS(Investments_Clean!$A$2:$A$150,A8,Investments_Clean!$D$2:$D$150,"DFI/Impact",Investments_Clean!$F$2:$F$150,"Accepted"))>0,1,0)) | CA8: 0 | CC8: =IF(I8="","",IFERROR(IF(INDEX(Macro_Lookup!$B$2:$B$31,MATCH(I8,Macro_Lookup!$A$2:$A$31,0))="","",INDEX(Macro_Lookup!$B$2:$B$31,MATCH(I8,Macro_Lookup!$A$2:$A$31,0))),"")) -> 6.52 | CD8: =IF(I8="","",IFERROR(IF(INDEX(Macro_Lookup!$C$2:$C$31,MATCH(I8,Macro_Lookup!$A$2:$A$31,0))="","",INDEX(Macro_Lookup!$C$2:$C$31,MATCH(I8,Macro_Lookup!$A$2:$A$31,0))),"")) -> 6.22 | CE8: =IF(BJ8="","",IFERROR(IF(INDEX(Macro_Lookup!$B$2:$B$31,MATCH(BJ8,Macro_Lookup!$A$2:$A$31,0))="","",INDEX(Macro_Lookup!$B$2:$B$31,MATCH(BJ8,Macro_Lookup!$A$2:$A$31,0))),"")) | CF8: =IF(BJ8="","",IFERROR(IF(INDEX(Macro_Lookup!$C$2:$C$31,MATCH(BJ8,Macro_Lookup!$A$2:$A$31,0))="","",INDEX(Macro_Lookup!$C$2:$C$31,MATCH(BJ8,Macro_Lookup!$A$2:$A$31,0))),"")) | CG8: 4
A9: BD-ST-008 | B9: Ucash | C9: Bangladesh | D9: Dhaka | E9: 0 | F9: Corporate division/subsidiary | G9: BD-ST-005 | I9: 2013 | K9: year | L9: 46295 | M9: =IF(I9="","",(YEAR(L9)-I9)*12+MONTH(L9)-IF(J9="",1,J9)) -> 164 | N9: =IF(M9="","",ROUND(M9/12,2)) -> 13.67 | O9: Fintech / Payments | P9: Fintech | Q9: MFS Payments | R9: 0 | S9: 0 | T9: 0 | U9: 0 | V9: 0 | W9: 0 | X9: Closed (migrated users to Upay, 2021) | Y9: 3 | Z9: 1 | AA9: 0 | AF9: =IF(SUMIF(Founders_Clean!$A$2:$A$159,A9,Founders_Clean!$C$2:$C$159)=0,"",SUMIF(Founders_Clean!$A$2:$A$159,A9,Founders_Clean!$C$2:$C$159)) -> 1 | AG9: =IF(AF9="","",SUMIF(Founders_Clean!$A$2:$A$159,A9,Founders_Clean!$D$2:$D$159)) -> 0 | AH9: =IF(AF9="","",SUMIF(Founders_Clean!$A$2:$A$159,A9,Founders_Clean!$E$2:$E$159)) -> 0 | AI9: =IF(AF9="","",IF((AG9+AH9)=0,"",AH9/(AG9+AH9))) | AJ9: =IF(AI9="","",IF(AH9>0,1,0)) | AK9: =IF(AI9="","",ROUND(1-(AI9^2+(1-AI9)^2),3)) | AT9: 150 | AU9: 51-200 | AV9: LinkedIn (Public_Macro_Data) | AX9: Closed | AY9: High | AZ9: Closed 2021; users migrated to Upay (BD-ST-005) | BA9: 0 | BB9: 0 | BC9: 1 | BD9: 2021 | BF9: =IF(OR(I9="",BC9=""),"",IF(BC9=1,(BD9-I9)*12+IF(BE9="",7,BE9)-IF(J9="",1,J9),M9)) -> 102 | BG9: 0 | BH9: 0 | BI9: none | BK9: 0 | BL9: =COUNTIFS(Investments_Clean!$A$2:$A$150,A9,Investments_Clean!$F$2:$F$150,"Accepted") -> 1 | BM9: =IF(BL9=0,"",IF((COUNTIFS(Investments_Clean!$A$2:$A$150,A9,Investments_Clean!$D$2:$D$150,"VC/PE",Investments_Clean!$F$2:$F$150,"Accepted"))>0,1,0)) -> 0 | BN9: =IF(BL9=0,"",IF((COUNTIFS(Investments_Clean!$A$2:$A$150,A9,Investments_Clean!$D$2:$D$150,"Angel",Investments_Clean!$F$2:$F$150,"Accepted"))>0,1,0)) -> 0 | BO9: =IF(BL9=0,"",IF((COUNTIFS(Investments_Clean!$A$2:$A$150,A9,Investments_Clean!$D$2:$D$150,"Accelerator",Investments_Clean!$F$2:$F$150,"Accepted"))>0,1,0)) -> 0 | BP9: =IF(BL9=0,"",IF((COUNTIFS(Investments_Clean!$A$2:$A$150,A9,Investments_Clean!$D$2:$D$150,"Corporate",Investments_Clean!$F$2:$F$150,"Accepted"))>0,1,0)) -> 0 | BQ9: =IF(BL9=0,"",IF((COUNTIFS(Investments_Clean!$A$2:$A$150,A9,Investments_Clean!$D$2:$D$150,"Government",Investments_Clean!$F$2:$F$150,"Accepted"))>0,1,0)) -> 0 | BR9: =IF(BL9=0,"",IF((COUNTIFS(Investments_Clean!$A$2:$A$150,A9,Investments_Clean!$D$2:$D$150,"Grant/Philanthropic",Investments_Clean!$F$2:$F$150,"Accepted")+COUNTIFS(Investments_Clean!$A$2:$A$150,A9,Investments_Clean!$D$2:$D$150,"DFI/Impact",Investments_Clean!$F$2:$F$150,"Accepted"))>0,1,0)) -> 0 | CA9: 0 | CC9: =IF(I9="","",IFERROR(IF(INDEX(Macro_Lookup!$B$2:$B$31,MATCH(I9,Macro_Lookup!$A$2:$A$31,0))="","",INDEX(Macro_Lookup!$B$2:$B$31,MATCH(I9,Macro_Lookup!$A$2:$A$31,0))),"")) -> 6.01 | CD9: =IF(I9="","",IFERROR(IF(INDEX(Macro_Lookup!$C$2:$C$31,MATCH(I9,Macro_Lookup!$A$2:$A$31,0))="","",INDEX(Macro_Lookup!$C$2:$C$31,MATCH(I9,Macro_Lookup!$A$2:$A$31,0))),"")) -> 7.53 | CE9: =IF(BJ9="","",IFERROR(IF(INDEX(Macro_Lookup!$B$2:$B$31,MATCH(BJ9,Macro_Lookup!$A$2:$A$31,0))="","",INDEX(Macro_Lookup!$B$2:$B$31,MATCH(BJ9,Macro_Lookup!$A$2:$A$31,0))),"")) | CF9: =IF(BJ9="","",IFERROR(IF(INDEX(Macro_Lookup!$C$2:$C$31,MATCH(BJ9,Macro_Lookup!$A$2:$A$31,0))="","",INDEX(Macro_Lookup!$C$2:$C$31,MATCH(BJ9,Macro_Lookup!$A$2:$A$31,0))),"")) | CG9: 3
A10: BD-ST-009 | B10: AamarPay | C10: Bangladesh | D10: Dhaka | E10: 0 | F10: Independent startup | I10: 2015 | K10: year | L10: 46295 | M10: =IF(I10="","",(YEAR(L10)-I10)*12+MONTH(L10)-IF(J10="",1,J10)) -> 140 | N10: =IF(M10="","",ROUND(M10/12,2)) -> 11.67 | O10: Fintech / Payments | P10: Fintech | Q10: Payment Gateway (PSO) | R10: 0 | S10: 0 | T10: 0 | U10: 0 | V10: 0 | W10: 0 | X10: Active | Y10: 3 | Z10: 1 | AF10: =IF(SUMIF(Founders_Clean!$A$2:$A$159,A10,Founders_Clean!$C$2:$C$159)=0,"",SUMIF(Founders_Clean!$A$2:$A$159,A10,Founders_Clean!$C$2:$C$159)) -> 1 | AG10: =IF(AF10="","",SUMIF(Founders_Clean!$A$2:$A$159,A10,Founders_Clean!$D$2:$D$159)) -> 1 | AH10: =IF(AF10="","",SUMIF(Founders_Clean!$A$2:$A$159,A10,Founders_Clean!$E$2:$E$159)) -> 0 | AI10: =IF(AF10="","",IF((AG10+AH10)=0,"",AH10/(AG10+AH10))) -> 0 | AJ10: =IF(AI10="","",IF(AH10>0,1,0)) -> 0 | AK10: =IF(AI10="","",ROUND(1-(AI10^2+(1-AI10)^2),3)) -> 0 | AM10: 1 | AN10: Bachelor's | AO10: 1 | AP10: 1 | AQ10: 1 | AR10: 10 | AS10: 10 | AT10: 100 | AU10: 51-200 | AV10: LinkedIn (Public_Macro_Data) | AX10: Active | AY10: High | AZ10: Acquired by Simpaisa March 2026; still operating | BA10: 1 | BB10: 0 | BC10: 0 | BF10: =IF(OR(I10="",BC10=""),"",IF(BC10=1,(BD10-I10)*12+IF(BE10="",7,BE10)-IF(J10="",1,J10),M10)) -> 140 | BG10: 1 | BH10: 1100000 | BI10: cumulative | BJ10: 2026 | BK10: 1 | BL10: =COUNTIFS(Investments_Clean!$A$2:$A$150,A10,Investments_Clean!$F$2:$F$150,"Accepted") -> 2 | BM10: =IF(BL10=0,"",IF((COUNTIFS(Investments_Clean!$A$2:$A$150,A10,Investments_Clean!$D$2:$D$150,"VC/PE",Investments_Clean!$F$2:$F$150,"Accepted"))>0,1,0)) -> 0 | BN10: =IF(BL10=0,"",IF((COUNTIFS(Investments_Clean!$A$2:$A$150,A10,Investments_Clean!$D$2:$D$150,"Angel",Investments_Clean!$F$2:$F$150,"Accepted"))>0,1,0)) -> 1 | BO10: =IF(BL10=0,"",IF((COUNTIFS(Investments_Clean!$A$2:$A$150,A10,Investments_Clean!$D$2:$D$150,"Accelerator",Investments_Clean!$F$2:$F$150,"Accepted"))>0,1,0)) -> 0 | BP10: =IF(BL10=0,"",IF((COUNTIFS(Investments_Clean!$A$2:$A$150,A10,Investments_Clean!$D$2:$D$150,"Corporate",Investments_Clean!$F$2:$F$150,"Accepted"))>0,1,0)) -> 1 | BQ10: =IF(BL10=0,"",IF((COUNTIFS(Investments_Clean!$A$2:$A$150,A10,Investments_Clean!$D$2:$D$150,"Government",Investments_Clean!$F$2:$F$150,"Accepted"))>0,1,0)) -> 0 | BR10: =IF(BL10=0,"",IF((COUNTIFS(Investments_Clean!$A$2:$A$150,A10,Investments_Clean!$D$2:$D$150,"Grant/Philanthropic",Investments_Clean!$F$2:$F$150,"Accepted")+COUNTIFS(Investments_Clean!$A$2:$A$150,A10,Investments_Clean!$D$2:$D$150,"DFI/Impact",Investments_Clean!$F$2:$F$150,"Accepted"))>0,1,0)) -> 0 | CA10: 0 | CC10: =IF(I10="","",IFERROR(IF(INDEX(Macro_Lookup!$B$2:$B$31,MATCH(I10,Macro_Lookup!$A$2:$A$31,0))="","",INDEX(Macro_Lookup!$B$2:$B$31,MATCH(I10,Macro_Lookup!$A$2:$A$31,0))),"")) -> 6.55 | CD10: =IF(I10="","",IFERROR(IF(INDEX(Macro_Lookup!$C$2:$C$31,MATCH(I10,Macro_Lookup!$A$2:$A$31,0))="","",INDEX(Macro_Lookup!$C$2:$C$31,MATCH(I10,Macro_Lookup!$A$2:$A$31,0))),"")) -> 6.4 | CE10: =IF(BJ10="","",IFERROR(IF(INDEX(Macro_Lookup!$B$2:$B$31,MATCH(BJ10,Macro_Lookup!$A$2:$A$31,0))="","",INDEX(Macro_Lookup!$B$2:$B$31,MATCH(BJ10,Macro_Lookup!$A$2:$A$31,0))),"")) | CF10: =IF(BJ10="","",IFERROR(IF(INDEX(Macro_Lookup!$C$2:$C$31,MATCH(BJ10,Macro_Lookup!$A$2:$A$31,0))="","",INDEX(Macro_Lookup!$C$2:$C$31,MATCH(BJ10,Macro_Lookup!$A$2:$A$31,0))),"")) -> 9.16 | CG10: 3
A11: BD-ST-010 | B11: SSLCOMMERZ | C11: Bangladesh | D11: Dhaka | E11: 0 | F11: Independent startup | I11: 2010 | K11: year | L11: 46295 | M11: =IF(I11="","",(YEAR(L11)-I11)*12+MONTH(L11)-IF(J11="",1,J11)) -> 200 | N11: =IF(M11="","",ROUND(M11/12,2)) -> 16.67 | O11: Fintech / Payments | P11: Fintech | Q11: Payment Gateway (PSO) | R11: 0 | S11: 0 | T11: 0 | U11: 0 | V11: 0 | W11: 0 | X11: Active | Y11: 3 | Z11: 1 | AF11: =IF(SUMIF(Founders_Clean!$A$2:$A$159,A11,Founders_Clean!$C$2:$C$159)=0,"",SUMIF(Founders_Clean!$A$2:$A$159,A11,Founders_Clean!$C$2:$C$159)) -> 1 | AG11: =IF(AF11="","",SUMIF(Founders_Clean!$A$2:$A$159,A11,Founders_Clean!$D$2:$D$159)) -> 1 | AH11: =IF(AF11="","",SUMIF(Founders_Clean!$A$2:$A$159,A11,Founders_Clean!$E$2:$E$159)) -> 0 | AI11: =IF(AF11="","",IF((AG11+AH11)=0,"",AH11/(AG11+AH11))) -> 0 | AJ11: =IF(AI11="","",IF(AH11>0,1,0)) -> 0 | AK11: =IF(AI11="","",ROUND(1-(AI11^2+(1-AI11)^2),3)) -> 0 | AM11: 2 | AN11: Master's/MBA/professional | AO11: 1 | AP11: 1 | AQ11: 1 | AR11: 25 | AS11: 25 | AT11: 275 | AU11: 201-500 | AV11: LinkedIn (Public_Macro_Data) | AX11: Active | AY11: High | BA11: 0 | BB11: 0 | BC11: 0 | BF11: =IF(OR(I11="",BC11=""),"",IF(BC11=1,(BD11-I11)*12+IF(BE11="",7,BE11)-IF(J11="",1,J11),M11)) -> 200 | BG11: 0 | BH11: 0 | BI11: none | BK11: 0 | BL11: =COUNTIFS(Investments_Clean!$A$2:$A$150,A11,Investments_Clean!$F$2:$F$150,"Accepted") -> 0 | BM11: =IF(BL11=0,"",IF((COUNTIFS(Investments_Clean!$A$2:$A$150,A11,Investments_Clean!$D$2:$D$150,"VC/PE",Investments_Clean!$F$2:$F$150,"Accepted"))>0,1,0)) | BN11: =IF(BL11=0,"",IF((COUNTIFS(Investments_Clean!$A$2:$A$150,A11,Investments_Clean!$D$2:$D$150,"Angel",Investments_Clean!$F$2:$F$150,"Accepted"))>0,1,0)) | BO11: =IF(BL11=0,"",IF((COUNTIFS(Investments_Clean!$A$2:$A$150,A11,Investments_Clean!$D$2:$D$150,"Accelerator",Investments_Clean!$F$2:$F$150,"Accepted"))>0,1,0)) | BP11: =IF(BL11=0,"",IF((COUNTIFS(Investments_Clean!$A$2:$A$150,A11,Investments_Clean!$D$2:$D$150,"Corporate",Investments_Clean!$F$2:$F$150,"Accepted"))>0,1,0)) | BQ11: =IF(BL11=0,"",IF((COUNTIFS(Investments_Clean!$A$2:$A$150,A11,Investments_Clean!$D$2:$D$150,"Government",Investments_Clean!$F$2:$F$150,"Accepted"))>0,1,0)) | BR11: =IF(BL11=0,"",IF((COUNTIFS(Investments_Clean!$A$2:$A$150,A11,Investments_Clean!$D$2:$D$150,"Grant/Philanthropic",Investments_Clean!$F$2:$F$150,"Accepted")+COUNTIFS(Investments_Clean!$A$2:$A$150,A11,Investments_Clean!$D$2:$D$150,"DFI/Impact",Investments_Clean!$F$2:$F$150,"Accepted"))>0,1,0)) | CA11: 0 | CC11: =IF(I11="","",IFERROR(IF(INDEX(Macro_Lookup!$B$2:$B$31,MATCH(I11,Macro_Lookup!$A$2:$A$31,0))="","",INDEX(Macro_Lookup!$B$2:$B$31,MATCH(I11,Macro_Lookup!$A$2:$A$31,0))),"")) -> 5.57 | CD11: =IF(I11="","",IFERROR(IF(INDEX(Macro_Lookup!$C$2:$C$31,MATCH(I11,Macro_Lookup!$A$2:$A$31,0))="","",INDEX(Macro_Lookup!$C$2:$C$31,MATCH(I11,Macro_Lookup!$A$2:$A$31,0))),"")) -> 7.3 | CE11: =IF(BJ11="","",IFERROR(IF(INDEX(Macro_Lookup!$B$2:$B$31,MATCH(BJ11,Macro_Lookup!$A$2:$A$31,0))="","",INDEX(Macro_Lookup!$B$2:$B$31,MATCH(BJ11,Macro_Lookup!$A$2:$A$31,0))),"")) | CF11: =IF(BJ11="","",IFERROR(IF(INDEX(Macro_Lookup!$C$2:$C$31,MATCH(BJ11,Macro_Lookup!$A$2:$A$31,0))="","",INDEX(Macro_Lookup!$C$2:$C$31,MATCH(BJ11,Macro_Lookup!$A$2:$A$31,0))),"")) | CG11: 3
A12: BD-ST-011 | B12: Muthopay | C12: Bangladesh | D12: Dhaka | E12: 0 | F12: Independent startup | K12: unknown | L12: 46295 | M12: =IF(I12="","",(YEAR(L12)-I12)*12+MONTH(L12)-IF(J12="",1,J12)) | N12: =IF(M12="","",ROUND(M12/12,2)) | O12: Fintech / Payments | P12: Fintech | Q12: Payment Gateway (Bluetooth / low-bandwidth transactions) | R12: 0 | S12: 0 | T12: 0 | U12: 0 | V12: 0 | W12: 1 | X12: Active | Y12: 3 | Z12: 1 | AA12: 0 | AF12: =IF(SUMIF(Founders_Clean!$A$2:$A$159,A12,Founders_Clean!$C$2:$C$159)=0,"",SUMIF(Founders_Clean!$A$2:$A$159,A12,Founders_Clean!$C$2:$C$159)) -> 1 | AG12: =IF(AF12="","",SUMIF(Founders_Clean!$A$2:$A$159,A12,Founders_Clean!$D$2:$D$159)) -> 1 | AH12: =IF(AF12="","",SUMIF(Founders_Clean!$A$2:$A$159,A12,Founders_Clean!$E$2:$E$159)) -> 0 | AI12: =IF(AF12="","",IF((AG12+AH12)=0,"",AH12/(AG12+AH12))) -> 0 | AJ12: =IF(AI12="","",IF(AH12>0,1,0)) -> 0 | AK12: =IF(AI12="","",ROUND(1-(AI12^2+(1-AI12)^2),3)) -> 0 | AQ12: 1 | AR12: 17 | AS12: 17 | AT12: 5.5 | AU12: 1-10 | AV12: Founders_Team | AX12: Active | AY12: High | BA12: 0 | BB12: 0 | BC12: 0 | BF12: =IF(OR(I12="",BC12=""),"",IF(BC12=1,(BD12-I12)*12+IF(BE12="",7,BE12)-IF(J12="",1,J12),M12)) | BG12: 1 | BH12: 37100 | BI12: round | BJ12: 2020 | BK12: 1 | BL12: =COUNTIFS(Investments_Clean!$A$2:$A$150,A12,Investments_Clean!$F$2:$F$150,"Accepted") -> 1 | BM12: =IF(BL12=0,"",IF((COUNTIFS(Investments_Clean!$A$2:$A$150,A12,Investments_Clean!$D$2:$D$150,"VC/PE",Investments_Clean!$F$2:$F$150,"Accepted"))>0,1,0)) -> 0 | BN12: =IF(BL12=0,"",IF((COUNTIFS(Investments_Clean!$A$2:$A$150,A12,Investments_Clean!$D$2:$D$150,"Angel",Investments_Clean!$F$2:$F$150,"Accepted"))>0,1,0)) -> 0 | BO12: =IF(BL12=0,"",IF((COUNTIFS(Investments_Clean!$A$2:$A$150,A12,Investments_Clean!$D$2:$D$150,"Accelerator",Investments_Clean!$F$2:$F$150,"Accepted"))>0,1,0)) -> 1 | BP12: =IF(BL12=0,"",IF((COUNTIFS(Investments_Clean!$A$2:$A$150,A12,Investments_Clean!$D$2:$D$150,"Corporate",Investments_Clean!$F$2:$F$150,"Accepted"))>0,1,0)) -> 0 | BQ12: =IF(BL12=0,"",IF((COUNTIFS(Investments_Clean!$A$2:$A$150,A12,Investments_Clean!$D$2:$D$150,"Government",Investments_Clean!$F$2:$F$150,"Accepted"))>0,1,0)) -> 0 | BR12: =IF(BL12=0,"",IF((COUNTIFS(Investments_Clean!$A$2:$A$150,A12,Investments_Clean!$D$2:$D$150,"Grant/Philanthropic",Investments_Clean!$F$2:$F$150,"Accepted")+COUNTIFS(Investments_Clean!$A$2:$A$150,A12,Investments_Clean!$D$2:$D$150,"DFI/Impact",Investments_Clean!$F$2:$F$150,"Accepted"))>0,1,0)) -> 0 | CA12: 0 | CC12: =IF(I12="","",IFERROR(IF(INDEX(Macro_Lookup!$B$2:$B$31,MATCH(I12,Macro_Lookup!$A$2:$A$31,0))="","",INDEX(Macro_Lookup!$B$2:$B$31,MATCH(I12,Macro_Lookup!$A$2:$A$31,0))),"")) | CD12: =IF(I12="","",IFERROR(IF(INDEX(Macro_Lookup!$C$2:$C$31,MATCH(I12,Macro_Lookup!$A$2:$A$31,0))="","",INDEX(Macro_Lookup!$C$2:$C$31,MATCH(I12,Macro_Lookup!$A$2:$A$31,0))),"")) | CE12: =IF(BJ12="","",IFERROR(IF(INDEX(Macro_Lookup!$B$2:$B$31,MATCH(BJ12,Macro_Lookup!$A$2:$A$31,0))="","",INDEX(Macro_Lookup!$B$2:$B$31,MATCH(BJ12,Macro_Lookup!$A$2:$A$31,0))),"")) -> 3.45 | CF12: =IF(BJ12="","",IFERROR(IF(INDEX(Macro_Lookup!$C$2:$C$31,MATCH(BJ12,Macro_Lookup!$A$2:$A$31,0))="","",INDEX(Macro_Lookup!$C$2:$C$31,MATCH(BJ12,Macro_Lookup!$A$2:$A$31,0))),"")) -> 5.69 | CG12: 4
A13: BD-ST-012 | B13: Tredx | C13: Bangladesh | D13: Dhaka | E13: 0 | F13: Independent startup | I13: 2022 | J13: 8 | K13: month | L13: 46295 | M13: =IF(I13="","",(YEAR(L13)-I13)*12+MONTH(L13)-IF(J13="",1,J13)) -> 49 | N13: =IF(M13="","",ROUND(M13/12,2)) -> 4.08 | O13: Fintech / Digital Lending | P13: Fintech | Q13: Digital supply chain finance / online invoice factoring marketplace | R13: 0 | S13: 0 | T13: 1 | U13: 0 | V13: 0 | W13: 0 | X13: Active (live production platform; integrated w/ Midland Bank PLC) | Y13: 3 | Z13: 1 | AA13: 0 | AC13: 0 | AD13: 0 | AE13: master | AF13: =IF(SUMIF(Founders_Clean!$A$2:$A$159,A13,Founders_Clean!$C$2:$C$159)=0,"",SUMIF(Founders_Clean!$A$2:$A$159,A13,Founders_Clean!$C$2:$C$159)) -> 3 | AG13: =IF(AF13="","",SUMIF(Founders_Clean!$A$2:$A$159,A13,Founders_Clean!$D$2:$D$159)) -> 3 | AH13: =IF(AF13="","",SUMIF(Founders_Clean!$A$2:$A$159,A13,Founders_Clean!$E$2:$E$159)) -> 0 | AI13: =IF(AF13="","",IF((AG13+AH13)=0,"",AH13/(AG13+AH13))) -> 0 | AJ13: =IF(AI13="","",IF(AH13>0,1,0)) -> 0 | AK13: =IF(AI13="","",ROUND(1-(AI13^2+(1-AI13)^2),3)) -> 0 | AM13: 3 | AN13: PhD | AO13: 0 | AP13: 0 | AQ13: 1 | AR13: 20 | AS13: 20 | AT13: 30.5 | AU13: 11-50 | AV13: Founders_Team | AX13: Active | AY13: High | BA13: 0 | BB13: 0 | BC13: 0 | BF13: =IF(OR(I13="",BC13=""),"",IF(BC13=1,(BD13-I13)*12+IF(BE13="",7,BE13)-IF(J13="",1,J13),M13)) -> 49 | BL13: =COUNTIFS(Investments_Clean!$A$2:$A$150,A13,Investments_Clean!$F$2:$F$150,"Accepted") -> 0 | BM13: =IF(BL13=0,"",IF((COUNTIFS(Investments_Clean!$A$2:$A$150,A13,Investments_Clean!$D$2:$D$150,"VC/PE",Investments_Clean!$F$2:$F$150,"Accepted"))>0,1,0)) | BN13: =IF(BL13=0,"",IF((COUNTIFS(Investments_Clean!$A$2:$A$150,A13,Investments_Clean!$D$2:$D$150,"Angel",Investments_Clean!$F$2:$F$150,"Accepted"))>0,1,0)) | BO13: =IF(BL13=0,"",IF((COUNTIFS(Investments_Clean!$A$2:$A$150,A13,Investments_Clean!$D$2:$D$150,"Accelerator",Investments_Clean!$F$2:$F$150,"Accepted"))>0,1,0)) | BP13: =IF(BL13=0,"",IF((COUNTIFS(Investments_Clean!$A$2:$A$150,A13,Investments_Clean!$D$2:$D$150,"Corporate",Investments_Clean!$F$2:$F$150,"Accepted"))>0,1,0)) | BQ13: =IF(BL13=0,"",IF((COUNTIFS(Investments_Clean!$A$2:$A$150,A13,Investments_Clean!$D$2:$D$150,"Government",Investments_Clean!$F$2:$F$150,"Accepted"))>0,1,0)) | BR13: =IF(BL13=0,"",IF((COUNTIFS(Investments_Clean!$A$2:$A$150,A13,Investments_Clean!$D$2:$D$150,"Grant/Philanthropic",Investments_Clean!$F$2:$F$150,"Accepted")+COUNTIFS(Investments_Clean!$A$2:$A$150,A13,Investments_Clean!$D$2:$D$150,"DFI/Impact",Investments_Clean!$F$2:$F$150,"Accepted"))>0,1,0)) | CA13: 0 | CC13: =IF(I13="","",IFERROR(IF(INDEX(Macro_Lookup!$B$2:$B$31,MATCH(I13,Macro_Lookup!$A$2:$A$31,0))="","",INDEX(Macro_Lookup!$B$2:$B$31,MATCH(I13,Macro_Lookup!$A$2:$A$31,0))),"")) -> 7.1 | CD13: =IF(I13="","",IFERROR(IF(INDEX(Macro_Lookup!$C$2:$C$31,MATCH(I13,Macro_Lookup!$A$2:$A$31,0))="","",INDEX(Macro_Lookup!$C$2:$C$31,MATCH(I13,Macro_Lookup!$A$2:$A$31,0))),"")) -> 7.7 | CE13: =IF(BJ13="","",IFERROR(IF(INDEX(Macro_Lookup!$B$2:$B$31,MATCH(BJ13,Macro_Lookup!$A$2:$A$31,0))="","",INDEX(Macro_Lookup!$B$2:$B$31,MATCH(BJ13,Macro_Lookup!$A$2:$A$31,0))),"")) | CF13: =IF(BJ13="","",IFERROR(IF(INDEX(Macro_Lookup!$C$2:$C$31,MATCH(BJ13,Macro_Lookup!$A$2:$A$31,0))="","",INDEX(Macro_Lookup!$C$2:$C$31,MATCH(BJ13,Macro_Lookup!$A$2:$A$31,0))),"")) | CG13: 3
A14: BD-ST-013 | B14: Chaldal | C14: Bangladesh | D14: Dhaka | E14: 0 | F14: Independent startup | I14: 2013 | J14: 9 | K14: month | L14: 46295 | M14: =IF(I14="","",(YEAR(L14)-I14)*12+MONTH(L14)-IF(J14="",1,J14)) -> 156 | N14: =IF(M14="","",ROUND(M14/12,2)) -> 13 | O14: E-commerce / Grocery | P14: E-commerce | Q14: Micro-warehouse ('nano-warehouse') grocery retail | R14: 0 | S14: 0 | T14: 0 | U14: 0 | V14: 0 | W14: 0 | X14: Active | Y14: 3 | Z14: 1 | AA14: 1 | AB14: Y Combinator | AF14: =IF(SUMIF(Founders_Clean!$A$2:$A$159,A14,Founders_Clean!$C$2:$C$159)=0,"",SUMIF(Founders_Clean!$A$2:$A$159,A14,Founders_Clean!$C$2:$C$159)) -> 3 | AG14: =IF(AF14="","",SUMIF(Founders_Clean!$A$2:$A$159,A14,Founders_Clean!$D$2:$D$159)) -> 3 | AH14: =IF(AF14="","",SUMIF(Founders_Clean!$A$2:$A$159,A14,Founders_Clean!$E$2:$E$159)) -> 0 | AI14: =IF(AF14="","",IF((AG14+AH14)=0,"",AH14/(AG14+AH14))) -> 0 | AJ14: =IF(AI14="","",IF(AH14>0,1,0)) -> 0 | AK14: =IF(AI14="","",ROUND(1-(AI14^2+(1-AI14)^2),3)) -> 0 | AM14: 2 | AN14: Master's/MBA/professional | AO14: 1 | AP14: 0.33333333 | AQ14: 1 | AR14: 10 | AS14: 10 | AT14: 1549.5 | AU14: 501+ | AV14: Founders_Team | AX14: Active | AY14: High | BA14: 0 | BB14: 0 | BC14: 0 | BF14: =IF(OR(I14="",BC14=""),"",IF(BC14=1,(BD14-I14)*12+IF(BE14="",7,BE14)-IF(J14="",1,J14),M14)) -> 156 | BG14: 1 | BH14: 30000000 | BI14: cumulative | BJ14: 2024 | BK14: 1 | BL14: =COUNTIFS(Investments_Clean!$A$2:$A$150,A14,Investments_Clean!$F$2:$F$150,"Accepted") -> 2 | BM14: =IF(BL14=0,"",IF((COUNTIFS(Investments_Clean!$A$2:$A$150,A14,Investments_Clean!$D$2:$D$150,"VC/PE",Investments_Clean!$F$2:$F$150,"Accepted"))>0,1,0)) -> 1 | BN14: =IF(BL14=0,"",IF((COUNTIFS(Investments_Clean!$A$2:$A$150,A14,Investments_Clean!$D$2:$D$150,"Angel",Investments_Clean!$F$2:$F$150,"Accepted"))>0,1,0)) -> 0 | BO14: =IF(BL14=0,"",IF((COUNTIFS(Investments_Clean!$A$2:$A$150,A14,Investments_Clean!$D$2:$D$150,"Accelerator",Investments_Clean!$F$2:$F$150,"Accepted"))>0,1,0)) -> 0 | BP14: =IF(BL14=0,"",IF((COUNTIFS(Investments_Clean!$A$2:$A$150,A14,Investments_Clean!$D$2:$D$150,"Corporate",Investments_Clean!$F$2:$F$150,"Accepted"))>0,1,0)) -> 0 | BQ14: =IF(BL14=0,"",IF((COUNTIFS(Investments_Clean!$A$2:$A$150,A14,Investments_Clean!$D$2:$D$150,"Government",Investments_Clean!$F$2:$F$150,"Accepted"))>0,1,0)) -> 0 | BR14: =IF(BL14=0,"",IF((COUNTIFS(Investments_Clean!$A$2:$A$150,A14,Investments_Clean!$D$2:$D$150,"Grant/Philanthropic",Investments_Clean!$F$2:$F$150,"Accepted")+COUNTIFS(Investments_Clean!$A$2:$A$150,A14,Investments_Clean!$D$2:$D$150,"DFI/Impact",Investments_Clean!$F$2:$F$150,"Accepted"))>0,1,0)) -> 0 | CA14: 0 | CC14: =IF(I14="","",IFERROR(IF(INDEX(Macro_Lookup!$B$2:$B$31,MATCH(I14,Macro_Lookup!$A$2:$A$31,0))="","",INDEX(Macro_Lookup!$B$2:$B$31,MATCH(I14,Macro_Lookup!$A$2:$A$31,0))),"")) -> 6.01 | CD14: =IF(I14="","",IFERROR(IF(INDEX(Macro_Lookup!$C$2:$C$31,MATCH(I14,Macro_Lookup!$A$2:$A$31,0))="","",INDEX(Macro_Lookup!$C$2:$C$31,MATCH(I14,Macro_Lookup!$A$2:$A$31,0))),"")) -> 7.53 | CE14: =IF(BJ14="","",IFERROR(IF(INDEX(Macro_Lookup!$B$2:$B$31,MATCH(BJ14,Macro_Lookup!$A$2:$A$31,0))="","",INDEX(Macro_Lookup!$B$2:$B$31,MATCH(BJ14,Macro_Lookup!$A$2:$A$31,0))),"")) -> 4.22 | CF14: =IF(BJ14="","",IFERROR(IF(INDEX(Macro_Lookup!$C$2:$C$31,MATCH(BJ14,Macro_Lookup!$A$2:$A$31,0))="","",INDEX(Macro_Lookup!$C$2:$C$31,MATCH(BJ14,Macro_Lookup!$A$2:$A$31,0))),"")) -> 9.7 | CG14: 2
A15: BD-ST-014 | B15: Daraz Bangladesh | C15: Bangladesh | D15: Dhaka | E15: 0 | F15: Independent startup (acquired by corporate) | I15: 2012 | K15: year | L15: 46295 | M15: =IF(I15="","",(YEAR(L15)-I15)*12+MONTH(L15)-IF(J15="",1,J15)) -> 176 | N15: =IF(M15="","",ROUND(M15/12,2)) -> 14.67 | O15: E-commerce / Marketplace | P15: E-commerce | Q15: Horizontal Marketplace | R15: 0 | S15: 0 | T15: 1 | U15: 0 | V15: 0 | W15: 0 | X15: Active | Y15: 3 | Z15: 1 | AA15: 0 | AF15: =IF(SUMIF(Founders_Clean!$A$2:$A$159,A15,Founders_Clean!$C$2:$C$159)=0,"",SUMIF(Founders_Clean!$A$2:$A$159,A15,Founders_Clean!$C$2:$C$159)) -> 2 | AG15: =IF(AF15="","",SUMIF(Founders_Clean!$A$2:$A$159,A15,Founders_Clean!$D$2:$D$159)) -> 0 | AH15: =IF(AF15="","",SUMIF(Founders_Clean!$A$2:$A$159,A15,Founders_Clean!$E$2:$E$159)) -> 0 | AI15: =IF(AF15="","",IF((AG15+AH15)=0,"",AH15/(AG15+AH15))) | AJ15: =IF(AI15="","",IF(AH15>0,1,0)) | AK15: =IF(AI15="","",ROUND(1-(AI15^2+(1-AI15)^2),3)) | AT15: 1000 | AU15: 501+ | AV15: LinkedIn (Public_Macro_Data) | AX15: Active | AY15: High | BA15: 1 | BB15: 0 | BC15: 0 | BF15: =IF(OR(I15="",BC15=""),"",IF(BC15=1,(BD15-I15)*12+IF(BE15="",7,BE15)-IF(J15="",1,J15),M15)) -> 176 | BK15: 1 | BL15: =COUNTIFS(Investments_Clean!$A$2:$A$150,A15,Investments_Clean!$F$2:$F$150,"Accepted") -> 1 | BM15: =IF(BL15=0,"",IF((COUNTIFS(Investments_Clean!$A$2:$A$150,A15,Investments_Clean!$D$2:$D$150,"VC/PE",Investments_Clean!$F$2:$F$150,"Accepted"))>0,1,0)) -> 0 | BN15: =IF(BL15=0,"",IF((COUNTIFS(Investments_Clean!$A$2:$A$150,A15,Investments_Clean!$D$2:$D$150,"Angel",Investments_Clean!$F$2:$F$150,"Accepted"))>0,1,0)) -> 0 | BO15: =IF(BL15=0,"",IF((COUNTIFS(Investments_Clean!$A$2:$A$150,A15,Investments_Clean!$D$2:$D$150,"Accelerator",Investments_Clean!$F$2:$F$150,"Accepted"))>0,1,0)) -> 0 | BP15: =IF(BL15=0,"",IF((COUNTIFS(Investments_Clean!$A$2:$A$150,A15,Investments_Clean!$D$2:$D$150,"Corporate",Investments_Clean!$F$2:$F$150,"Accepted"))>0,1,0)) -> 1 | BQ15: =IF(BL15=0,"",IF((COUNTIFS(Investments_Clean!$A$2:$A$150,A15,Investments_Clean!$D$2:$D$150,"Government",Investments_Clean!$F$2:$F$150,"Accepted"))>0,1,0)) -> 0 | BR15: =IF(BL15=0,"",IF((COUNTIFS(Investments_Clean!$A$2:$A$150,A15,Investments_Clean!$D$2:$D$150,"Grant/Philanthropic",Investments_Clean!$F$2:$F$150,"Accepted")+COUNTIFS(Investments_Clean!$A$2:$A$150,A15,Investments_Clean!$D$2:$D$150,"DFI/Impact",Investments_Clean!$F$2:$F$150,"Accepted"))>0,1,0)) -> 0 | CA15: 0 | CC15: =IF(I15="","",IFERROR(IF(INDEX(Macro_Lookup!$B$2:$B$31,MATCH(I15,Macro_Lookup!$A$2:$A$31,0))="","",INDEX(Macro_Lookup!$B$2:$B$31,MATCH(I15,Macro_Lookup!$A$2:$A$31,0))),"")) -> 6.52 | CD15: =IF(I15="","",IFERROR(IF(INDEX(Macro_Lookup!$C$2:$C$31,MATCH(I15,Macro_Lookup!$A$2:$A$31,0))="","",INDEX(Macro_Lookup!$C$2:$C$31,MATCH(I15,Macro_Lookup!$A$2:$A$31,0))),"")) -> 6.22 | CE15: =IF(BJ15="","",IFERROR(IF(INDEX(Macro_Lookup!$B$2:$B$31,MATCH(BJ15,Macro_Lookup!$A$2:$A$31,0))="","",INDEX(Macro_Lookup!$B$2:$B$31,MATCH(BJ15,Macro_Lookup!$A$2:$A$31,0))),"")) | CF15: =IF(BJ15="","",IFERROR(IF(INDEX(Macro_Lookup!$C$2:$C$31,MATCH(BJ15,Macro_Lookup!$A$2:$A$31,0))="","",INDEX(Macro_Lookup!$C$2:$C$31,MATCH(BJ15,Macro_Lookup!$A$2:$A$31,0))),"")) | CG15: 4
A16: BD-ST-015 | B16: AjkerDeal | C16: Bangladesh | D16: Dhaka | E16: 0 | F16: Independent startup | I16: 2011 | K16: year | L16: 46295 | M16: =IF(I16="","",(YEAR(L16)-I16)*12+MONTH(L16)-IF(J16="",1,J16)) -> 188 | N16: =IF(M16="","",ROUND(M16/12,2)) -> 15.67 | O16: E-commerce / Marketplace | P16: E-commerce | Q16: B2C Marketplace | R16: 0 | S16: 1 | T16: 1 | U16: 0 | V16: 0 | W16: 0 | X16: Active | Y16: 3 | Z16: 1 | AF16: =IF(SUMIF(Founders_Clean!$A$2:$A$159,A16,Founders_Clean!$C$2:$C$159)=0,"",SUMIF(Founders_Clean!$A$2:$A$159,A16,Founders_Clean!$C$2:$C$159)) -> 1 | AG16: =IF(AF16="","",SUMIF(Founders_Clean!$A$2:$A$159,A16,Founders_Clean!$D$2:$D$159)) -> 1 | AH16: =IF(AF16="","",SUMIF(Founders_Clean!$A$2:$A$159,A16,Founders_Clean!$E$2:$E$159)) -> 0 | AI16: =IF(AF16="","",IF((AG16+AH16)=0,"",AH16/(AG16+AH16))) -> 0 | AJ16: =IF(AI16="","",IF(AH16>0,1,0)) -> 0 | AK16: =IF(AI16="","",ROUND(1-(AI16^2+(1-AI16)^2),3)) -> 0 | AM16: 2 | AN16: Master's/MBA/professional | AO16: 0 | AP16: 0 | AQ16: 1 | AR16: 25 | AS16: 25 | AT16: 75 | AU16: 51-200 | AV16: LinkedIn (Public_Macro_Data) | AX16: Active | AY16: High | BA16: 0 | BB16: 0 | BC16: 0 | BF16: =IF(OR(I16="",BC16=""),"",IF(BC16=1,(BD16-I16)*12+IF(BE16="",7,BE16)-IF(J16="",1,J16),M16)) -> 188 | BL16: =COUNTIFS(Investments_Clean!$A$2:$A$150,A16,Investments_Clean!$F$2:$F$150,"Accepted") -> 0 | BM16: =IF(BL16=0,"",IF((COUNTIFS(Investments_Clean!$A$2:$A$150,A16,Investments_Clean!$D$2:$D$150,"VC/PE",Investments_Clean!$F$2:$F$150,"Accepted"))>0,1,0)) | BN16: =IF(BL16=0,"",IF((COUNTIFS(Investments_Clean!$A$2:$A$150,A16,Investments_Clean!$D$2:$D$150,"Angel",Investments_Clean!$F$2:$F$150,"Accepted"))>0,1,0)) | BO16: =IF(BL16=0,"",IF((COUNTIFS(Investments_Clean!$A$2:$A$150,A16,Investments_Clean!$D$2:$D$150,"Accelerator",Investments_Clean!$F$2:$F$150,"Accepted"))>0,1,0)) | BP16: =IF(BL16=0,"",IF((COUNTIFS(Investments_Clean!$A$2:$A$150,A16,Investments_Clean!$D$2:$D$150,"Corporate",Investments_Clean!$F$2:$F$150,"Accepted"))>0,1,0)) | BQ16: =IF(BL16=0,"",IF((COUNTIFS(Investments_Clean!$A$2:$A$150,A16,Investments_Clean!$D$2:$D$150,"Government",Investments_Clean!$F$2:$F$150,"Accepted"))>0,1,0)) | BR16: =IF(BL16=0,"",IF((COUNTIFS(Investments_Clean!$A$2:$A$150,A16,Investments_Clean!$D$2:$D$150,"Grant/Philanthropic",Investments_Clean!$F$2:$F$150,"Accepted")+COUNTIFS(Investments_Clean!$A$2:$A$150,A16,Investments_Clean!$D$2:$D$150,"DFI/Impact",Investments_Clean!$F$2:$F$150,"Accepted"))>0,1,0)) | CA16: 0 | CC16: =IF(I16="","",IFERROR(IF(INDEX(Macro_Lookup!$B$2:$B$31,MATCH(I16,Macro_Lookup!$A$2:$A$31,0))="","",INDEX(Macro_Lookup!$B$2:$B$31,MATCH(I16,Macro_Lookup!$A$2:$A$31,0))),"")) -> 6.46 | CD16: =IF(I16="","",IFERROR(IF(INDEX(Macro_Lookup!$C$2:$C$31,MATCH(I16,Macro_Lookup!$A$2:$A$31,0))="","",INDEX(Macro_Lookup!$C$2:$C$31,MATCH(I16,Macro_Lookup!$A$2:$A$31,0))),"")) -> 11.4 | CE16: =IF(BJ16="","",IFERROR(IF(INDEX(Macro_Lookup!$B$2:$B$31,MATCH(BJ16,Macro_Lookup!$A$2:$A$31,0))="","",INDEX(Macro_Lookup!$B$2:$B$31,MATCH(BJ16,Macro_Lookup!$A$2:$A$31,0))),"")) | CF16: =IF(BJ16="","",IFERROR(IF(INDEX(Macro_Lookup!$C$2:$C$31,MATCH(BJ16,Macro_Lookup!$A$2:$A$31,0))="","",INDEX(Macro_Lookup!$C$2:$C$31,MATCH(BJ16,Macro_Lookup!$A$2:$A$31,0))),"")) | CG16: 5
A17: BD-ST-016 | B17: Rokomari.com | C17: Bangladesh | D17: Dhaka | E17: 0 | F17: Independent startup | I17: 2012 | K17: year | L17: 46295 | M17: =IF(I17="","",(YEAR(L17)-I17)*12+MONTH(L17)-IF(J17="",1,J17)) -> 176 | N17: =IF(M17="","",ROUND(M17/12,2)) -> 14.67 | O17: E-commerce / Books | P17: E-commerce | Q17: Online Bookstore | R17: 0 | S17: 0 | T17: 0 | U17: 0 | V17: 0 | W17: 0 | X17: Active | Y17: 3 | Z17: 1 | AA17: 0 | AF17: =IF(SUMIF(Founders_Clean!$A$2:$A$159,A17,Founders_Clean!$C$2:$C$159)=0,"",SUMIF(Founders_Clean!$A$2:$A$159,A17,Founders_Clean!$C$2:$C$159)) -> 5 | AG17: =IF(AF17="","",SUMIF(Founders_Clean!$A$2:$A$159,A17,Founders_Clean!$D$2:$D$159)) -> 5 | AH17: =IF(AF17="","",SUMIF(Founders_Clean!$A$2:$A$159,A17,Founders_Clean!$E$2:$E$159)) -> 0 | AI17: =IF(AF17="","",IF((AG17+AH17)=0,"",AH17/(AG17+AH17))) -> 0 | AJ17: =IF(AI17="","",IF(AH17>0,1,0)) -> 0 | AK17: =IF(AI17="","",ROUND(1-(AI17^2+(1-AI17)^2),3)) -> 0 | AM17: 2 | AN17: Master's/MBA/professional | AO17: 1 | AP17: 1 | AQ17: 1 | AR17: 10 | AS17: 10 | AT17: 150 | AU17: 51-200 | AV17: Founders_Team | AX17: Active | AY17: High | BA17: 0 | BB17: 0 | BC17: 0 | BF17: =IF(OR(I17="",BC17=""),"",IF(BC17=1,(BD17-I17)*12+IF(BE17="",7,BE17)-IF(J17="",1,J17),M17)) -> 176 | BG17: 0 | BH17: 0 | BI17: none | BK17: 0 | BL17: =COUNTIFS(Investments_Clean!$A$2:$A$150,A17,Investments_Clean!$F$2:$F$150,"Accepted") -> 0 | BM17: =IF(BL17=0,"",IF((COUNTIFS(Investments_Clean!$A$2:$A$150,A17,Investments_Clean!$D$2:$D$150,"VC/PE",Investments_Clean!$F$2:$F$150,"Accepted"))>0,1,0)) | BN17: =IF(BL17=0,"",IF((COUNTIFS(Investments_Clean!$A$2:$A$150,A17,Investments_Clean!$D$2:$D$150,"Angel",Investments_Clean!$F$2:$F$150,"Accepted"))>0,1,0)) | BO17: =IF(BL17=0,"",IF((COUNTIFS(Investments_Clean!$A$2:$A$150,A17,Investments_Clean!$D$2:$D$150,"Accelerator",Investments_Clean!$F$2:$F$150,"Accepted"))>0,1,0)) | BP17: =IF(BL17=0,"",IF((COUNTIFS(Investments_Clean!$A$2:$A$150,A17,Investments_Clean!$D$2:$D$150,"Corporate",Investments_Clean!$F$2:$F$150,"Accepted"))>0,1,0)) | BQ17: =IF(BL17=0,"",IF((COUNTIFS(Investments_Clean!$A$2:$A$150,A17,Investments_Clean!$D$2:$D$150,"Government",Investments_Clean!$F$2:$F$150,"Accepted"))>0,1,0)) | BR17: =IF(BL17=0,"",IF((COUNTIFS(Investments_Clean!$A$2:$A$150,A17,Investments_Clean!$D$2:$D$150,"Grant/Philanthropic",Investments_Clean!$F$2:$F$150,"Accepted")+COUNTIFS(Investments_Clean!$A$2:$A$150,A17,Investments_Clean!$D$2:$D$150,"DFI/Impact",Investments_Clean!$F$2:$F$150,"Accepted"))>0,1,0)) | CA17: 0 | CC17: =IF(I17="","",IFERROR(IF(INDEX(Macro_Lookup!$B$2:$B$31,MATCH(I17,Macro_Lookup!$A$2:$A$31,0))="","",INDEX(Macro_Lookup!$B$2:$B$31,MATCH(I17,Macro_Lookup!$A$2:$A$31,0))),"")) -> 6.52 | CD17: =IF(I17="","",IFERROR(IF(INDEX(Macro_Lookup!$C$2:$C$31,MATCH(I17,Macro_Lookup!$A$2:$A$31,0))="","",INDEX(Macro_Lookup!$C$2:$C$31,MATCH(I17,Macro_Lookup!$A$2:$A$31,0))),"")) -> 6.22 | CE17: =IF(BJ17="","",IFERROR(IF(INDEX(Macro_Lookup!$B$2:$B$31,MATCH(BJ17,Macro_Lookup!$A$2:$A$31,0))="","",INDEX(Macro_Lookup!$B$2:$B$31,MATCH(BJ17,Macro_Lookup!$A$2:$A$31,0))),"")) | CF17: =IF(BJ17="","",IFERROR(IF(INDEX(Macro_Lookup!$C$2:$C$31,MATCH(BJ17,Macro_Lookup!$A$2:$A$31,0))="","",INDEX(Macro_Lookup!$C$2:$C$31,MATCH(BJ17,Macro_Lookup!$A$2:$A$31,0))),"")) | CG17: 2
A18: BD-ST-017 | B18: Bikroy.com | C18: Bangladesh | D18: Dhaka | E18: 0 | F18: Independent startup | I18: 2012 | K18: year | L18: 46295 | M18: =IF(I18="","",(YEAR(L18)-I18)*12+MONTH(L18)-IF(J18="",1,J18)) -> 176 | N18: =IF(M18="","",ROUND(M18/12,2)) -> 14.67 | O18: E-commerce / Classifieds | P18: E-commerce | Q18: Online Classifieds | R18: 0 | S18: 0 | T18: 0 | U18: 0 | V18: 0 | W18: 0 | X18: Acquired | Y18: 3 | Z18: 1 | AA18: 0 | AF18: =IF(SUMIF(Founders_Clean!$A$2:$A$159,A18,Founders_Clean!$C$2:$C$159)=0,"",SUMIF(Founders_Clean!$A$2:$A$159,A18,Founders_Clean!$C$2:$C$159)) -> 1 | AG18: =IF(AF18="","",SUMIF(Founders_Clean!$A$2:$A$159,A18,Founders_Clean!$D$2:$D$159)) -> 0 | AH18: =IF(AF18="","",SUMIF(Founders_Clean!$A$2:$A$159,A18,Founders_Clean!$E$2:$E$159)) -> 1 | AI18: =IF(AF18="","",IF((AG18+AH18)=0,"",AH18/(AG18+AH18))) -> 1 | AJ18: =IF(AI18="","",IF(AH18>0,1,0)) -> 1 | AK18: =IF(AI18="","",ROUND(1-(AI18^2+(1-AI18)^2),3)) -> 0 | AM18: 1 | AN18: Bachelor's | AO18: 0 | AP18: 0 | AQ18: 0 | AR18: 13 | AS18: 13 | AT18: 427 | AU18: 201-500 | AV18: Founders_Team | AX18: Acquired | AY18: High | AZ18: Acquired by Jiji.com May 2026 | BA18: 1 | BB18: 0 | BC18: 0 | BF18: =IF(OR(I18="",BC18=""),"",IF(BC18=1,(BD18-I18)*12+IF(BE18="",7,BE18)-IF(J18="",1,J18),M18)) -> 176 | BG18: 1 | BH18: 1300000 | BI18: round | BJ18: 2021 | BK18: 1 | BL18: =COUNTIFS(Investments_Clean!$A$2:$A$150,A18,Investments_Clean!$F$2:$F$150,"Accepted") -> 0 | BM18: =IF(BL18=0,"",IF((COUNTIFS(Investments_Clean!$A$2:$A$150,A18,Investments_Clean!$D$2:$D$150,"VC/PE",Investments_Clean!$F$2:$F$150,"Accepted"))>0,1,0)) | BN18: =IF(BL18=0,"",IF((COUNTIFS(Investments_Clean!$A$2:$A$150,A18,Investments_Clean!$D$2:$D$150,"Angel",Investments_Clean!$F$2:$F$150,"Accepted"))>0,1,0)) | BO18: =IF(BL18=0,"",IF((COUNTIFS(Investments_Clean!$A$2:$A$150,A18,Investments_Clean!$D$2:$D$150,"Accelerator",Investments_Clean!$F$2:$F$150,"Accepted"))>0,1,0)) | BP18: =IF(BL18=0,"",IF((COUNTIFS(Investments_Clean!$A$2:$A$150,A18,Investments_Clean!$D$2:$D$150,"Corporate",Investments_Clean!$F$2:$F$150,"Accepted"))>0,1,0)) | BQ18: =IF(BL18=0,"",IF((COUNTIFS(Investments_Clean!$A$2:$A$150,A18,Investments_Clean!$D$2:$D$150,"Government",Investments_Clean!$F$2:$F$150,"Accepted"))>0,1,0)) | BR18: =IF(BL18=0,"",IF((COUNTIFS(Investments_Clean!$A$2:$A$150,A18,Investments_Clean!$D$2:$D$150,"Grant/Philanthropic",Investments_Clean!$F$2:$F$150,"Accepted")+COUNTIFS(Investments_Clean!$A$2:$A$150,A18,Investments_Clean!$D$2:$D$150,"DFI/Impact",Investments_Clean!$F$2:$F$150,"Accepted"))>0,1,0)) | CA18: 0 | CC18: =IF(I18="","",IFERROR(IF(INDEX(Macro_Lookup!$B$2:$B$31,MATCH(I18,Macro_Lookup!$A$2:$A$31,0))="","",INDEX(Macro_Lookup!$B$2:$B$31,MATCH(I18,Macro_Lookup!$A$2:$A$31,0))),"")) -> 6.52 | CD18: =IF(I18="","",IFERROR(IF(INDEX(Macro_Lookup!$C$2:$C$31,MATCH(I18,Macro_Lookup!$A$2:$A$31,0))="","",INDEX(Macro_Lookup!$C$2:$C$31,MATCH(I18,Macro_Lookup!$A$2:$A$31,0))),"")) -> 6.22 | CE18: =IF(BJ18="","",IFERROR(IF(INDEX(Macro_Lookup!$B$2:$B$31,MATCH(BJ18,Macro_Lookup!$A$2:$A$31,0))="","",INDEX(Macro_Lookup!$B$2:$B$31,MATCH(BJ18,Macro_Lookup!$A$2:$A$31,0))),"")) -> 6.94 | CF18: =IF(BJ18="","",IFERROR(IF(INDEX(Macro_Lookup!$C$2:$C$31,MATCH(BJ18,Macro_Lookup!$A$2:$A$31,0))="","",INDEX(Macro_Lookup!$C$2:$C$31,MATCH(BJ18,Macro_Lookup!$A$2:$A$31,0))),"")) -> 5.55 | CG18: 2
